Workbook

Sheet Pharma Group AG
A1: Employee ID | B1: Gender | C1: Job Level after FY20 promotions | D1: Job Position fy20 | E1: New hire FY20? | F1: FY20 Performance Rating | G1: Promotion in FY21? | H1: In base group for Promotion FY21 | I1: Target hire balance | J1: FY20 leaver? | K1: In base group for turnover FY20 | L1: Department @01.07.2020 | M1: Leaver FY | N1: Job Level after FY21 promotions | O1: Position fy21 | P1: Last Department in FY20 | Q1: FTE group | R1: Time type | S1: Department & JL group PRA status | T1: Department & JL group for PRA | U1: Job Level group PRA status | V1: Job Level group for PRA | W1: Time in Job Level @01.07.2020 | X1: Job Level before FY20 promotions | Y1: Promotion in FY20? | Z1: FY19 Performance Rating | AA1: Age group | AB1: Age @01.07.2020 | AC1: Nationality 1 | AD1: Region group: nationality 1 | AE1: Broad region group: nationality 1 | AF1: Last hire date | AG1: Years since last hire | AH1: Rand
A2: 1 | B2: Male | C2: 6 | D2: Junior Officer | E2: N | F2: 2 | G2: No | H2: No | I2: 0.5 | J2: Yes | K2: Y | L2: Operations | M2: FY20 | N2: 0 | O2: NOT AVAILABLE | P2: Operations | Q2: Full Time | R2: Full Time | S2: =IF(T2="","",INDEX('Backing 4'!U:U,MATCH(T2,'Backing 4'!T:T,0))) -> #N/A | T2: =IF(O2="","",IF(D2="1 - Executive","",D2&" & "&P2)) -> Junior Officer & Operations | U2: =IF(V2="","",INDEX('Backing 4'!Z:Z,MATCH(V2,'Backing 4'!Y:Y,0))) -> #N/A | V2: =IF(O2="","",IF(D2="1 - Executive","",D2)) -> Junior Officer | W2: 3 | X2: =IF(E2="Y","",IF(Y2="Y",INDEX('Backing 2'!B:B,MATCH(D2,'Backing 2'!C:C,0)),D2)) -> Junior Officer | Y2: N | Z2: 3 | AA2: 30 to 39 | AB2: 37 | AC2: Spain | AD2: Europe | AE2: Europe | AF2: 42826 | AG2: 3 | AH2: =RAND() -> 0.031824451
A3: 2 | B3: Female | C3: 4 | D3: Manager | E3: N | F3: 3 | G3: No | H3: Yes | I3: 0.5 | J3: No | K3: Y | L3: Sales & Marketing | M3: 0 | N3: 4 | O3: Manager | P3: Sales & Marketing | Q3: Full Time | R3: Full Time | S3: =IF(T3="","",INDEX('Backing 4'!U:U,MATCH(T3,'Backing 4'!T:T,0))) -> #N/A | T3: =IF(O3="","",IF(D3="1 - Executive","",D3&" & "&P3)) -> Manager & Sales & Marketing | U3: =IF(V3="","",INDEX('Backing 4'!Z:Z,MATCH(V3,'Backing 4'!Y:Y,0))) -> #N/A | V3: =IF(O3="","",IF(D3="1 - Executive","",D3)) -> Manager | W3: 3 | X3: =IF(E3="Y","",IF(Y3="Y",INDEX('Backing 2'!B:B,MATCH(D3,'Backing 2'!C:C,0)),D3)) -> Manager | Y3: N | Z3: 0 | AA3: 30 to 39 | AB3: 37 | AC3: Germany | AD3: Europe | AE3: Europe | AF3: 42826 | AG3: 3 | AH3: =RAND() -> 0.5350691
A4: 3 | B4: Male | C4: 2 | D4: Director | E4: N | F4: 2 | G4: No | H4: Yes | I4: 0.5 | J4: No | K4: Y | L4: Strategy | M4: 0 | N4: 2 | O4: Director | P4: Strategy | Q4: Full Time | R4: Full Time | S4: =IF(T4="","",INDEX('Backing 4'!U:U,MATCH(T4,'Backing 4'!T:T,0))) -> #N/A | T4: =IF(O4="","",IF(D4="1 - Executive","",D4&" & "&P4)) -> Director & Strategy | U4: Uneven - Men benefit | V4: =IF(O4="","",IF(D4="1 - Executive","",D4)) -> Director | W4: 3 | X4: =IF(E4="Y","",IF(Y4="Y",INDEX('Backing 2'!B:B,MATCH(D4,'Backing 2'!C:C,0)),D4)) -> Director | Y4: N | Z4: 3 | AA4: 30 to 39 | AB4: 35 | AC4: Switzerland | AD4: Switzerland | AE4: Switzerland | AF4: 42095 | AG4: 5 | AH4: =RAND() -> 0.61767753
A5: 4 | B5: Male | C5: 4 | D5: Manager | E5: N | F5: 3 | G5: No | H5: Yes | I5: 0.5 | J5: No | K5: Y | L5: HR | M5: 0 | N5: 4 | O5: Manager | P5: HR | Q5: Full Time | R5: Full Time | S5: =IF(T5="","",INDEX('Backing 4'!U:U,MATCH(T5,'Backing 4'!T:T,0))) -> #N/A | T5: =IF(O5="","",IF(D5="1 - Executive","",D5&" & "&P5)) -> Manager & HR | U5: =IF(V5="","",INDEX('Backing 4'!Z:Z,MATCH(V5,'Backing 4'!Y:Y,0))) -> #N/A | V5: =IF(O5="","",IF(D5="1 - Executive","",D5)) -> Manager | W5: 3 | X5: =IF(E5="Y","",IF(Y5="Y",INDEX('Backing 2'!B:B,MATCH(D5,'Backing 2'!C:C,0)),D5)) -> Manager | Y5: N | Z5: 3 | AA5: 30 to 39 | AB5: 32 | AC5: Germany | AD5: Europe | AE5: Europe | AF5: 41000 | AG5: 8 | AH5: =RAND() -> 0.54846764
A6: 5 | B6: Female | C6: 6 | D6: Junior Officer | E6: N | F6: 2 | G6: No | H6: Yes | I6: 0.5 | J6: No | K6: Y | L6: Sales & Marketing | M6: 0 | N6: 6 | O6: Junior Officer | P6: Sales & Marketing | Q6: Full Time | R6: Full Time | S6: =IF(T6="","",INDEX('Backing 4'!U:U,MATCH(T6,'Backing 4'!T:T,0))) -> #N/A | T6: =IF(O6="","",IF(D6="1 - Executive","",D6&" & "&P6)) -> Junior Officer & Sales & Marketing | U6: =IF(V6="","",INDEX('Backing 4'!Z:Z,MATCH(V6,'Backing 4'!Y:Y,0))) -> #N/A | V6: =IF(O6="","",IF(D6="1 - Executive","",D6)) -> Junior Officer | W6: 1 | X6: =IF(E6="Y","",IF(Y6="Y",INDEX('Backing 2'!B:B,MATCH(D6,'Backing 2'!C:C,0)),D6)) -> Junior Officer | Y6: N | Z6: 0 | AA6: 20 to 29 | AB6: 28 | AC6: Switzerland | AD6: Switzerland | AE6: Switzerland | AF6: 43556 | AG6: 1 | AH6: =RAND() -> 0.60822902
A7: 6 | B7: Female | C7: 4 | D7: Manager | E7: Y | F7: 0 | G7: No | H7: No | I7: 0.5 | J7: No | K7: N | L7: Internal Services | M7: 0 | N7: 4 | O7: Manager | P7: Internal Services | Q7: Full Time | R7: Full Time | S7: =IF(T7="","",INDEX('Backing 4'!U:U,MATCH(T7,'Backing 4'!T:T,0))) -> #N/A | T7: =IF(O7="","",IF(D7="1 - Executive","",D7&" & "&P7)) -> Manager & Internal Services | U7: =IF(V7="","",INDEX('Backing 4'!Z:Z,MATCH(V7,'Backing 4'!Y:Y,0))) -> #N/A | V7: =IF(O7="","",IF(D7="1 - Executive","",D7)) -> Manager | W7: 0 | X7: =IF(E7="Y","",IF(Y7="Y",INDEX('Backing 2'!B:B,MATCH(D7,'Backing 2'!C:C,0)),D7)) | Y7: N | Z7: 0 | AA7: 40 to 49 | AB7: 42 | AC7: Italy | AD7: Europe | AE7: Europe | AF7: 43922 | AG7: 0 | AH7: =RAND() -> 0.20159608
A8: 7 | B8: Male | C8: 3 | D8: Senior Manager | E8: Y | F8: 0 | G8: No | H8: No | I8: 0.5 | J8: No | K8: N | L8: Operations | M8: 0 | N8: 3 | O8: Senior Manager | P8: Operations | Q8: Full Time | R8: Full Time | S8: =IF(T8="","",INDEX('Backing 4'!U:U,MATCH(T8,'Backing 4'!T:T,0))) -> #N/A | T8: =IF(O8="","",IF(D8="1 - Executive","",D8&" & "&P8)) -> Senior Manager & Operations | U8: =IF(V8="","",INDEX('Backing 4'!Z:Z,MATCH(V8,'Backing 4'!Y:Y,0))) -> #N/A | V8: =IF(O8="","",IF(D8="1 - Executive","",D8)) -> Senior Manager | W8: 0 | X8: =IF(E8="Y","",IF(Y8="Y",INDEX('Backing 2'!B:B,MATCH(D8,'Backing 2'!C:C,0)),D8)) | Y8: N | Z8: 0 | AA8: 30 to 39 | AB8: 35 | AC8: Italy | AD8: Europe | AE8: Europe | AF8: 43922 | AG8: 0 | AH8: =RAND() -> 0.25034098
A9: 8 | B9: Female | C9: 5 | D9: Senior Officer | E9: N | F9: 2 | G9: No | H9: Yes | I9: 0.5 | J9: No | K9: Y | L9: HR | M9: 0 | N9: 5 | O9: Senior Officer | P9: HR | Q9: Full Time | R9: Full Time | S9: =IF(T9="","",INDEX('Backing 4'!U:U,MATCH(T9,'Backing 4'!T:T,0))) -> #N/A | T9: =IF(O9="","",IF(D9="1 - Executive","",D9&" & "&P9)) -> Senior Officer & HR | U9: =IF(V9="","",INDEX('Backing 4'!Z:Z,MATCH(V9,'Backing 4'!Y:Y,0))) -> #N/A | V9: =IF(O9="","",IF(D9="1 - Executive","",D9)) -> Senior Officer | W9: 3 | X9: =IF(E9="Y","",IF(Y9="Y",INDEX('Backing 2'!B:B,MATCH(D9,'Backing 2'!C:C,0)),D9)) -> Senior Officer | Y9: N | Z9: 3 | AA9: 30 to 39 | AB9: 34 | AC9: Switzerland | AD9: Switzerland | AE9: Switzerland | AF9: 41365 | AG9: 7 | AH9: =RAND() -> 0.3430192
A10: 9 | B10: Female | C10: 6 | D10: Junior Officer | E10: N | F10: 3 | G10: No | H10: Yes | I10: 0.5 | J10: No | K10: Y | L10: Sales & Marketing | M10: 0 | N10: 6 | O10: Junior Officer | P10: Sales & Marketing | Q10: Full Time | R10: Full Time | S10: =IF(T10="","",INDEX('Backing 4'!U:U,MATCH(T10,'Backing 4'!T:T,0))) -> #N/A | T10: =IF(O10="","",IF(D10="1 - Executive","",D10&" & "&P10)) -> Junior Officer & Sales & Marketing | U10: =IF(V10="","",INDEX('Backing 4'!Z:Z,MATCH(V10,'Backing 4'!Y:Y,0))) -> #N/A | V10: =IF(O10="","",IF(D10="1 - Executive","",D10)) -> Junior Officer | W10: 1 | X10: =IF(E10="Y","",IF(Y10="Y",INDEX('Backing 2'!B:B,MATCH(D10,'Backing 2'!C:C,0)),D10)) -> Junior Officer | Y10: N | Z10: 0 | AA10: 20 to 29 | AB10: 26 | AC10: United States | AD10: Americas | AE10: Elsewhere | AF10: 43556 | AG10: 1 | AH10: =RAND() -> 0.90030771
A11: 10 | B11: Male | C11: 6 | D11: Junior Officer | E11: N | F11: 3 | G11: No | H11: Yes | I11: 0.5 | J11: No | K11: Y | L11: Internal Services | M11: 0 | N11: 6 | O11: Junior Officer | P11: Internal Services | Q11: Full Time | R11: Full Time | S11: =IF(T11="","",INDEX('Backing 4'!U:U,MATCH(T11,'Backing 4'!T:T,0))) -> #N/A | T11: =IF(O11="","",IF(D11="1 - Executive","",D11&" & "&P11)) -> Junior Officer & Internal Services | U11: =IF(V11="","",INDEX('Backing 4'!Z:Z,MATCH(V11,'Backing 4'!Y:Y,0))) -> #N/A | V11: =IF(O11="","",IF(D11="1 - Executive","",D11)) -> Junior Officer | W11: 2 | X11: =IF(E11="Y","",IF(Y11="Y",INDEX('Backing 2'!B:B,MATCH(D11,'Backing 2'!C:C,0)),D11)) -> Junior Officer | Y11: N | Z11: 3 | AA11: 20 to 29 | AB11: 24 | AC11: Switzerland | AD11: Switzerland | AE11: Switzerland | AF11: 43191 | AG11: 2 | AH11: =RAND() -> 0.86170496
A12: 11 | B12: Male | C12: 4 | D12: Manager | E12: N | F12: 3 | G12: No | H12: Yes | I12: 0.5 | J12: No | K12: Y | L12: Operations | M12: 0 | N12: 4 | O12: Manager | P12: Operations | Q12: Full Time | R12: Full Time | S12: =IF(T12="","",INDEX('Backing 4'!U:U,MATCH(T12,'Backing 4'!T:T,0))) -> #N/A | T12: =IF(O12="","",IF(D12="1 - Executive","",D12&" & "&P12)) -> Manager & Operations | U12: =IF(V12="","",INDEX('Backing 4'!Z:Z,MATCH(V12,'Backing 4'!Y:Y,0))) -> #N/A | V12: =IF(O12="","",IF(D12="1 - Executive","",D12)) -> Manager | W12: 2 | X12: =IF(E12="Y","",IF(Y12="Y",INDEX('Backing 2'!B:B,MATCH(D12,'Backing 2'!C:C,0)),D12)) -> Manager | Y12: N | Z12: 2 | AA12: 30 to 39 | AB12: 34 | AC12: Switzerland | AD12: Switzerland | AE12: Switzerland | AF12: 40634 | AG12: 9 | AH12: =RAND() -> 0.83521974
A13: 12 | B13: Female | C13: 6 | D13: Junior Officer | E13: N | F13: 2 | G13: Yes | H13: Yes | I13: 0.5 | J13: No | K13: Y | L13: Strategy | M13: 0 | N13: 5 | O13: Senior Officer | P13: Strategy | Q13: Full Time | R13: Full Time | S13: =IF(T13="","",INDEX('Backing 4'!U:U,MATCH(T13,'Backing 4'!T:T,0))) -> #N/A | T13: =IF(O13="","",IF(D13="1 - Executive","",D13&" & "&P13)) -> Junior Officer & Strategy | U13: =IF(V13="","",INDEX('Backing 4'!Z:Z,MATCH(V13,'Backing 4'!Y:Y,0))) -> #N/A | V13: =IF(O13="","",IF(D13="1 - Executive","",D13)) -> Junior Officer | W13: 3 | X13: =IF(E13="Y","",IF(Y13="Y",INDEX('Backing 2'!B:B,MATCH(D13,'Backing 2'!C:C,0)),D13)) -> Junior Officer | Y13: N | Z13: 3 | AA13: 30 to 39 | AB13: 34 | AC13: France | AD13: Europe | AE13: Europe | AF13: 42826 | AG13: 3 | AH13: =RAND() -> 0.94991732
A14: 13 | B14: Male | C14: 5 | D14: Senior Officer | E14: N | F14: 2 | G14: No | H14: Yes | I14: 0.5 | J14: No | K14: Y | L14: Operations | M14: 0 | N14: 5 | O14: Senior Officer | P14: Operations | Q14: Full Time | R14: Full Time | S14: =IF(T14="","",INDEX('Backing 4'!U:U,MATCH(T14,'Backing 4'!T:T,0))) -> #N/A | T14: =IF(O14="","",IF(D14="1 - Executive","",D14&" & "&P14)) -> Senior Officer & Operations | U14: =IF(V14="","",INDEX('Backing 4'!Z:Z,MATCH(V14,'Backing 4'!Y:Y,0))) -> #N/A | V14: =IF(O14="","",IF(D14="1 - Executive","",D14)) -> Senior Officer | W14: 3 | X14: =IF(E14="Y","",IF(Y14="Y",INDEX('Backing 2'!B:B,MATCH(D14,'Backing 2'!C:C,0)),D14)) -> Senior Officer | Y14: N | Z14: 3 | AA14: 20 to 29 | AB14: 29 | AC14: Germany | AD14: Europe | AE14: Europe | AF14: 42095 | AG14: 5 | AH14: =RAND() -> 0.76110033
A15: 14 | B15: Male | C15: 6 | D15: Junior Officer | E15: N | F15: 2 | G15: No | H15: Yes | I15: 0.5 | J15: No | K15: Y | L15: Operations | M15: 0 | N15: 6 | O15: Junior Officer | P15: Operations | Q15: Full Time | R15: Full Time | S15: =IF(T15="","",INDEX('Backing 4'!U:U,MATCH(T15,'Backing 4'!T:T,0))) -> #N/A | T15: =IF(O15="","",IF(D15="1 - Executive","",D15&" & "&P15)) -> Junior Officer & Operations | U15: =IF(V15="","",INDEX('Backing 4'!Z:Z,MATCH(V15,'Backing 4'!Y:Y,0))) -> #N/A | V15: =IF(O15="","",IF(D15="1 - Executive","",D15)) -> Junior Officer | W15: 3 | X15: =IF(E15="Y","",IF(Y15="Y",INDEX('Backing 2'!B:B,MATCH(D15,'Backing 2'!C:C,0)),D15)) -> Junior Officer | Y15: N | Z15: 2 | AA15: 20 to 29 | AB15: 20 | AC15: Switzerland | AD15: Switzerland | AE15: Switzerland | AF15: 42826 | AG15: 3 | AH15: =RAND() -> 0.79949266
A16: 15 | B16: Male | C16: 6 | D16: Junior Officer | E16: N | F16: 3 | G16: No | H16: No | I16: 0.5 | J16: Yes | K16: Y | L16: Internal Services | M16: FY20 | N16: 0 | O16: NOT AVAILABLE | P16: Internal Services | Q16: Full Time | R16: Full Time | S16: =IF(T16="","",INDEX('Backing 4'!U:U,MATCH(T16,'Backing 4'!T:T,0))) -> #N/A | T16: =IF(O16="","",IF(D16="1 - Executive","",D16&" & "&P16)) -> Junior Officer & Internal Services | U16: =IF(V16="","",INDEX('Backing 4'!Z:Z,MATCH(V16,'Backing 4'!Y:Y,0))) -> #N/A | V16: =IF(O16="","",IF(D16="1 - Executive","",D16)) -> Junior Officer | W16: 1 | X16: =IF(E16="Y","",IF(Y16="Y",INDEX('Backing 2'!B:B,MATCH(D16,'Backing 2'!C:C,0)),D16)) -> Junior Officer | Y16: N | Z16: 0 | AA16: 20 to 29 | AB16: 28 | AC16: France | AD16: Europe | AE16: Europe | AF16: 43556 | AG16: 1 | AH16: =RAND() -> 0.86687828
A17: 16 | B17: Male | C17: 4 | D17: Manager | E17: N | F17: 3 | G17: No | H17: Yes | I17: 0.5 | J17: No | K17: Y | L17: Strategy | M17: 0 | N17: 4 | O17: Manager | P17: Strategy | Q17: Full Time | R17: Full Time | S17: =IF(T17="","",INDEX('Backing 4'!U:U,MATCH(T17,'Backing 4'!T:T,0))) -> #N/A | T17: =IF(O17="","",IF(D17="1 - Executive","",D17&" & "&P17)) -> Manager & Strategy | U17: =IF(V17="","",INDEX('Backing 4'!Z:Z,MATCH(V17,'Backing 4'!Y:Y,0))) -> #N/A | V17: =IF(O17="","",IF(D17="1 - Executive","",D17)) -> Manager | W17: 3 | X17: =IF(E17="Y","",IF(Y17="Y",INDEX('Backing 2'!B:B,MATCH(D17,'Backing 2'!C:C,0)),D17)) -> Manager | Y17: N | Z17: 3 | AA17: 30 to 39 | AB17: 34 | AC17: Germany | AD17: Europe | AE17: Europe | AF17: 42095 | AG17: 5 | AH17: =RAND() -> 0.53698432
A18: 17 | B18: Male | C18: 6 | D18: Junior Officer | E18: N | F18: 3 | G18: No | H18: Yes | I18: 0.5 | J18: No | K18: Y | L18: Operations | M18: 0 | N18: 6 | O18: Junior Officer | P18: Operations | Q18: Full Time | R18: Full Time | S18: =IF(T18="","",INDEX('Backing 4'!U:U,MATCH(T18,'Backing 4'!T:T,0))) -> #N/A | T18: =IF(O18="","",IF(D18="1 - Executive","",D18&" & "&P18)) -> Junior Officer & Operations | U18: =IF(V18="","",INDEX('Backing 4'!Z:Z,MATCH(V18,'Backing 4'!Y:Y,0))) -> #N/A | V18: =IF(O18="","",IF(D18="1 - Executive","",D18)) -> Junior Officer | W18: 2 | X18: =IF(E18="Y","",IF(Y18="Y",INDEX('Backing 2'!B:B,MATCH(D18,'Backing 2'!C:C,0)),D18)) -> Junior Officer | Y18: N | Z18: 4 | AA18: 20 to 29 | AB18: 24 | AC18: Switzerland | AD18: Switzerland | AE18: Switzerland | AF18: 43191 | AG18: 2 | AH18: =RAND() -> 0.43319077
A19: 18 | B19: Female | C19: 6 | D19: Junior Officer | E19: N | F19: 2 | G19: Yes | H19: Yes | I19: 0.5 | J19: No | K19: Y | L19: Sales & Marketing | M19: 0 | N19: 5 | O19: Senior Officer | P19: Sales & Marketing | Q19: 0.8 | R19: Part Time | S19: =IF(T19="","",INDEX('Backing 4'!U:U,MATCH(T19,'Backing 4'!T:T,0))) -> #N/A | T19: =IF(O19="","",IF(D19="1 - Executive","",D19&" & "&P19)) -> Junior Officer & Sales & Marketing | U19: =IF(V19="","",INDEX('Backing 4'!Z:Z,MATCH(V19,'Backing 4'!Y:Y,0))) -> #N/A | V19: =IF(O19="","",IF(D19="1 - Executive","",D19)) -> Junior Officer | W19: 4 | X19: =IF(E19="Y","",IF(Y19="Y",INDEX('Backing 2'!B:B,MATCH(D19,'Backing 2'!C:C,0)),D19)) -> Junior Officer | Y19: N | Z19: 3 | AA19: 30 to 39 | AB19: 32 | AC19: Italy | AD19: Europe | AE19: Europe | AF19: 42461 | AG19: 4 | AH19: =RAND() -> 0.0089263429
A20: 19 | B20: Male | C20: 5 | D20: Senior Officer | E20: N | F20: 2 | G20: No | H20: Yes | I20: 0.5 | J20: No | K20: Y | L20: Sales & Marketing | M20: 0 | N20: 5 | O20: Senior Officer | P20: Sales & Marketing | Q20: Full Time | R20: Full Time | S20: =IF(T20="","",INDEX('Backing 4'!U:U,MATCH(T20,'Backing 4'!T:T,0))) -> #N/A | T20: =IF(O20="","",IF(D20="1 - Executive","",D20&" & "&P20)) -> Senior Officer & Sales & Marketing | U20: =IF(V20="","",INDEX('Backing 4'!Z:Z,MATCH(V20,'Backing 4'!Y:Y,0))) -> #N/A | V20: =IF(O20="","",IF(D20="1 - Executive","",D20)) -> Senior Officer | W20: 3 | X20: =IF(E20="Y","",IF(Y20="Y",INDEX('Backing 2'!B:B,MATCH(D20,'Backing 2'!C:C,0)),D20)) -> Senior Officer | Y20: N | Z20: 0 | AA20: 30 to 39 | AB20: 30 | AC20: Switzerland | AD20: Switzerland | AE20: Switzerland | AF20: 42826 | AG20: 3 | AH20: =RAND() -> 0.27118231
A21: 20 | B21: Female | C21: 5 | D21: Senior Officer | E21: N | F21: 2 | G21: No | H21: Yes | I21: 0.5 | J21: No | K21: Y | L21: Operations | M21: 0 | N21: 5 | O21: Senior Officer | P21: Operations | Q21: Full Time | R21: Full Time | S21: =IF(T21="","",INDEX('Backing 4'!U:U,MATCH(T21,'Backing 4'!T:T,0))) -> #N/A | T21: =IF(O21="","",IF(D21="1 - Executive","",D21&" & "&P21)) -> Senior Officer & Operations | U21: =IF(V21="","",INDEX('Backing 4'!Z:Z,MATCH(V21,'Backing 4'!Y:Y,0))) -> #N/A | V21: =IF(O21="","",IF(D21="1 - Executive","",D21)) -> Senior Officer | W21: 1 | X21: =IF(E21="Y","",IF(Y21="Y",INDEX('Backing 2'!B:B,MATCH(D21,'Backing 2'!C:C,0)),D21)) -> #N/A | Y21: Y | Z21: 1 | AA21: 30 to 39 | AB21: 32 | AC21: Germany | AD21: Europe | AE21: Europe | AF21: 41000 | AG21: 8 | AH21: =RAND() -> 0.97675532
A22: 21 | B22: Male | C22: 3 | D22: Senior Manager | E22: N | F22: 3 | G22: No | H22: No | I22: 0.5 | J22: Yes | K22: Y | L22: Strategy | M22: FY20 | N22: 0 | O22: NOT AVAILABLE | P22: Strategy | Q22: Full Time | R22: Full Time | S22: =IF(T22="","",INDEX('Backing 4'!U:U,MATCH(T22,'Backing 4'!T:T,0))) -> #N/A | T22: =IF(O22="","",IF(D22="1 - Executive","",D22&" & "&P22)) -> Senior Manager & Strategy | U22: =IF(V22="","",INDEX('Backing 4'!Z:Z,MATCH(V22,'Backing 4'!Y:Y,0))) -> #N/A | V22: =IF(O22="","",IF(D22="1 - Executive","",D22)) -> Senior Manager | W22: 7 | X22: =IF(E22="Y","",IF(Y22="Y",INDEX('Backing 2'!B:B,MATCH(D22,'Backing 2'!C:C,0)),D22)) -> Senior Manager | Y22: N | Z22: 3 | AA22: 30 to 39 | AB22: 31 | AC22: Switzerland | AD22: Switzerland | AE22: Switzerland | AF22: 41365 | AG22: 7 | AH22: =RAND() -> 0.76280176
A23: 22 | B23: Male | C23: 6 | D23: Junior Officer | E23: N | F23: 3 | G23: No | H23: No | I23: 0.5 | J23: Yes | K23: Y | L23: Sales & Marketing | M23: FY20 | N23: 0 | O23: NOT AVAILABLE | P23: Sales & Marketing | Q23: Full Time | R23: Full Time | S23: =IF(T23="","",INDEX('Backing 4'!U:U,MATCH(T23,'Backing 4'!T:T,0))) -> #N/A | T23: =IF(O23="","",IF(D23="1 - Executive","",D23&" & "&P23)) -> Junior Officer & Sales & Marketing | U23: =IF(V23="","",INDEX('Backing 4'!Z:Z,MATCH(V23,'Backing 4'!Y:Y,0))) -> #N/A | V23: =IF(O23="","",IF(D23="1 - Executive","",D23)) -> Junior Officer | W23: 3 | X23: =IF(E23="Y","",IF(Y23="Y",INDEX('Backing 2'!B:B,MATCH(D23,'Backing 2'!C:C,0)),D23)) -> Junior Officer | Y23: N | Z23: 3 | AA23: 20 to 29 | AB23: 26 | AC23: Switzerland | AD23: Switzerland | AE23: Switzerland | AF23: 42826 | AG23: 3 | AH23: =RAND() -> 0.8248517
A24: 23 | B24: Male | C24: 2 | D24: Director | E24: N | F24: 3 | G24: No | H24: Yes | I24: 0.5 | J24: No | K24: Y | L24: Internal Services | M24: 0 | N24: 2 | O24: Director | P24: Internal Services | Q24: Full Time | R24: Full Time | S24: =IF(T24="","",INDEX('Backing 4'!U:U,MATCH(T24,'Backing 4'!T:T,0))) -> #N/A | T24: =IF(O24="","",IF(D24="1 - Executive","",D24&" & "&P24)) -> Director & Internal Services | U24: Uneven - Men benefit | V24: =IF(O24="","",IF(D24="1 - Executive","",D24)) -> Director | W24: 5 | X24: =IF(E24="Y","",IF(Y24="Y",INDEX('Backing 2'!B:B,MATCH(D24,'Backing 2'!C:C,0)),D24)) -> Director | Y24: N | Z24: 0 | AA24: 40 to 49 | AB24: 44 | AC24: Switzerland | AD24: Switzerland | AE24: Switzerland | AF24: 42095 | AG24: 5 | AH24: =RAND() -> 0.98261432
A25: 24 | B25: Male | C25: 5 | D25: Senior Officer | E25: N | F25: 4 | G25: No | H25: Yes | I25: 0.5 | J25: No | K25: Y | L25: Sales & Marketing | M25: 0 | N25: 5 | O25: Senior Officer | P25: Sales & Marketing | Q25: Full Time | R25: Full Time | S25: =IF(T25="","",INDEX('Backing 4'!U:U,MATCH(T25,'Backing 4'!T:T,0))) -> #N/A | T25: =IF(O25="","",IF(D25="1 - Executive","",D25&" & "&P25)) -> Senior Officer & Sales & Marketing | U25: =IF(V25="","",INDEX('Backing 4'!Z:Z,MATCH(V25,'Backing 4'!Y:Y,0))) -> #N/A | V25: =IF(O25="","",IF(D25="1 - Executive","",D25)) -> Senior Officer | W25: 3 | X25: =IF(E25="Y","",IF(Y25="Y",INDEX('Backing 2'!B:B,MATCH(D25,'Backing 2'!C:C,0)),D25)) -> Senior Officer | Y25: N | Z25: 3 | AA25: 20 to 29 | AB25: 26 | AC25: United Kingdom | AD25: Europe | AE25: Europe | AF25: 41730 | AG25: 6 | AH25: =RAND() -> 0.27614627
A26: 25 | B26: Male | C26: 4 | D26: Manager | E26: N | F26: 2 | G26: No | H26: Yes | I26: 0.5 | J26: No | K26: Y | L26: Operations | M26: 0 | N26: 4 | O26: Manager | P26: Operations | Q26: Full Time | R26: Full Time | S26: =IF(T26="","",INDEX('Backing 4'!U:U,MATCH(T26,'Backing 4'!T:T,0))) -> #N/A | T26: =IF(O26="","",IF(D26="1 - Executive","",D26&" & "&P26)) -> Manager & Operations | U26: =IF(V26="","",INDEX('Backing 4'!Z:Z,MATCH(V26,'Backing 4'!Y:Y,0))) -> #N/A | V26: =IF(O26="","",IF(D26="1 - Executive","",D26)) -> Manager | W26: 3 | X26: =IF(E26="Y","",IF(Y26="Y",INDEX('Backing 2'!B:B,MATCH(D26,'Backing 2'!C:C,0)),D26)) -> Manager | Y26: N | Z26: 3 | AA26: 30 to 39 | AB26: 36 | AC26: France | AD26: Europe | AE26: Europe | AF26: 41730 | AG26: 6 | AH26: =RAND() -> 0.63869654
A27: 26 | B27: Male | C27: 6 | D27: Junior Officer | E27: N | F27: 2 | G27: No | H27: Yes | I27: 0.5 | J27: No | K27: Y | L27: Internal Services | M27: 0 | N27: 6 | O27: Junior Officer | P27: Internal Services | Q27: Full Time | R27: Full Time | S27: =IF(T27="","",INDEX('Backing 4'!U:U,MATCH(T27,'Backing 4'!T:T,0))) -> #N/A | T27: =IF(O27="","",IF(D27="1 - Executive","",D27&" & "&P27)) -> Junior Officer & Internal Services | U27: =IF(V27="","",INDEX('Backing 4'!Z:Z,MATCH(V27,'Backing 4'!Y:Y,0))) -> #N/A | V27: =IF(O27="","",IF(D27="1 - Executive","",D27)) -> Junior Officer | W27: 2 | X27: =IF(E27="Y","",IF(Y27="Y",INDEX('Backing 2'!B:B,MATCH(D27,'Backing 2'!C:C,0)),D27)) -> Junior Officer | Y27: N | Z27: 3 | AA27: 20 to 29 | AB27: 22 | AC27: Switzerland | AD27: Switzerland | AE27: Switzerland | AF27: 43191 | AG27: 2 | AH27: =RAND() -> 0.32928829
A28: 27 | B28: Female | C28: 5 | D28: Senior Officer | E28: N | F28: 3 | G28: No | H28: Yes | I28: 0.5 | J28: No | K28: Y | L28: Internal Services | M28: 0 | N28: 5 | O28: Senior Officer | P28: Internal Services | Q28: Full Time | R28: Full Time | S28: =IF(T28="","",INDEX('Backing 4'!U:U,MATCH(T28,'Backing 4'!T:T,0))) -> #N/A | T28: =IF(O28="","",IF(D28="1 - Executive","",D28&" & "&P28)) -> Senior Officer & Internal Services | U28: =IF(V28="","",INDEX('Backing 4'!Z:Z,MATCH(V28,'Backing 4'!Y:Y,0))) -> #N/A | V28: =IF(O28="","",IF(D28="1 - Executive","",D28)) -> Senior Officer | W28: 3 | X28: =IF(E28="Y","",IF(Y28="Y",INDEX('Backing 2'!B:B,MATCH(D28,'Backing 2'!C:C,0)),D28)) -> Senior Officer | Y28: N | Z28: 2 | AA28: 30 to 39 | AB28: 33 | AC28: Switzerland | AD28: Switzerland | AE28: Switzerland | AF28: 42461 | AG28: 4 | AH28: =RAND() -> 0.86209395
A29: 28 | B29: Male | C29: 5 | D29: Senior Officer | E29: N | F29: 4 | G29: No | H29: Yes | I29: 0.5 | J29: No | K29: Y | L29: Sales & Marketing | M29: 0 | N29: 5 | O29: Senior Officer | P29: Sales & Marketing | Q29: Full Time | R29: Full Time | S29: =IF(T29="","",INDEX('Backing 4'!U:U,MATCH(T29,'Backing 4'!T:T,0))) -> #N/A | T29: =IF(O29="","",IF(D29="1 - Executive","",D29&" & "&P29)) -> Senior Officer & Sales & Marketing | U29: =IF(V29="","",INDEX('Backing 4'!Z:Z,MATCH(V29,'Backing 4'!Y:Y,0))) -> #N/A | V29: =IF(O29="","",IF(D29="1 - Executive","",D29)) -> Senior Officer | W29: 2 | X29: =IF(E29="Y","",IF(Y29="Y",INDEX('Backing 2'!B:B,MATCH(D29,'Backing 2'!C:C,0)),D29)) -> Senior Officer | Y29: N | Z29: 2 | AA29: 20 to 29 | AB29: 27 | AC29: Italy | AD29: Europe | AE29: Europe | AF29: 42461 | AG29: 4 | AH29: =RAND() -> 0.79175936
A30: 29 | B30: Female | C30: 5 | D30: Senior Officer | E30: N | F30: 2 | G30: No | H30: Yes | I30: 0.5 | J30: No | K30: Y | L30: Finance | M30: 0 | N30: 5 | O30: Senior Officer | P30: Finance | Q30: Full Time | R30: Full Time | S30: =IF(T30="","",INDEX('Backing 4'!U:U,MATCH(T30,'Backing 4'!T:T,0))) -> #N/A | T30: =IF(O30="","",IF(D30="1 - Executive","",D30&" & "&P30)) -> Senior Officer & Finance | U30: =IF(V30="","",INDEX('Backing 4'!Z:Z,MATCH(V30,'Backing 4'!Y:Y,0))) -> #N/A | V30: =IF(O30="","",IF(D30="1 - Executive","",D30)) -> Senior Officer | W30: 2 | X30: =IF(E30="Y","",IF(Y30="Y",INDEX('Backing 2'!B:B,MATCH(D30,'Backing 2'!C:C,0)),D30)) -> Senior Officer | Y30: N | Z30: 3 | AA30: 30 to 39 | AB30: 32 | AC30: Italy | AD30: Europe | AE30: Europe | AF30: 42461 | AG30: 4 | AH30: =RAND() -> 0.96334358
A31: 30 | B31: Male | C31: 6 | D31: Junior Officer | E31: N | F31: 2 | G31: No | H31: Yes | I31: 0.5 | J31: No | K31: Y | L31: Operations | M31: 0 | N31: 6 | O31: Junior Officer | P31: Operations | Q31: Full Time | R31: Full Time | S31: =IF(T31="","",INDEX('Backing 4'!U:U,MATCH(T31,'Backing 4'!T:T,0))) -> #N/A | T31: =IF(O31="","",IF(D31="1 - Executive","",D31&" & "&P31)) -> Junior Officer & Operations | U31: =IF(V31="","",INDEX('Backing 4'!Z:Z,MATCH(V31,'Backing 4'!Y:Y,0))) -> #N/A | V31: =IF(O31="","",IF(D31="1 - Executive","",D31)) -> Junior Officer | W31: 1 | X31: =IF(E31="Y","",IF(Y31="Y",INDEX('Backing 2'!B:B,MATCH(D31,'Backing 2'!C:C,0)),D31)) -> Junior Officer | Y31: N | Z31: 0 | AA31: 20 to 29 | AB31: 25 | AC31: Switzerland | AD31: Switzerland | AE31: Switzerland | AF31: 43556 | AG31: 1 | AH31: =RAND() -> 0.10863048
A32: 31 | B32: Female | C32: 6 | D32: Junior Officer | E32: N | F32: 2 | G32: Yes | H32: Yes | I32: 0.5 | J32: No | K32: Y | L32: Operations | M32: 0 | N32: 5 | O32: Senior Officer | P32: Operations | Q32: Full Time | R32: Full Time | S32: =IF(T32="","",INDEX('Backing 4'!U:U,MATCH(T32,'Backing 4'!T:T,0))) -> #N/A | T32: =IF(O32="","",IF(D32="1 - Executive","",D32&" & "&P32)) -> Junior Officer & Operations | U32: =IF(V32="","",INDEX('Backing 4'!Z:Z,MATCH(V32,'Backing 4'!Y:Y,0))) -> #N/A | V32: =IF(O32="","",IF(D32="1 - Executive","",D32)) -> Junior Officer | W32: 3 | X32: =IF(E32="Y","",IF(Y32="Y",INDEX('Backing 2'!B:B,MATCH(D32,'Backing 2'!C:C,0)),D32)) -> Junior Officer | Y32: N | Z32: 2 | AA32: 30 to 39 | AB32: 33 | AC32: Switzerland | AD32: Switzerland | AE32: Switzerland | AF32: 42826 | AG32: 3 | AH32: =RAND() -> 0.57117019
A33: 32 | B33: Male | C33: 4 | D33: Manager | E33: N | F33: 1 | G33: Yes | H33: Yes | I33: 0.5 | J33: No | K33: Y | L33: Sales & Marketing | M33: 0 | N33: 3 | O33: Senior Manager | P33: Sales & Marketing | Q33: Full Time | R33: Full Time | S33: =IF(T33="","",INDEX('Backing 4'!U:U,MATCH(T33,'Backing 4'!T:T,0))) -> #N/A | T33: =IF(O33="","",IF(D33="1 - Executive","",D33&" & "&P33)) -> Manager & Sales & Marketing | U33: =IF(V33="","",INDEX('Backing 4'!Z:Z,MATCH(V33,'Backing 4'!Y:Y,0))) -> #N/A | V33: =IF(O33="","",IF(D33="1 - Executive","",D33)) -> Manager | W33: 2 | X33: =IF(E33="Y","",IF(Y33="Y",INDEX('Backing 2'!B:B,MATCH(D33,'Backing 2'!C:C,0)),D33)) -> Manager | Y33: N | Z33: 2 | AA33: 30 to 39 | AB33: 30 | AC33: Switzerland | AD33: Switzerland | AE33: Switzerland | AF33: 41000 | AG33: 8 | AH33: =RAND() -> 0.99664617
A34: 33 | B34: Male | C34: 4 | D34: Manager | E34: N | F34: 2 | G34: No | H34: Yes | I34: 0.5 | J34: No | K34: Y | L34: Sales & Marketing | M34: 0 | N34: 4 | O34: Manager | P34: Sales & Marketing | Q34: Full Time | R34: Full Time | S34: =IF(T34="","",INDEX('Backing 4'!U:U,MATCH(T34,'Backing 4'!T:T,0))) -> #N/A | T34: =IF(O34="","",IF(D34="1 - Executive","",D34&" & "&P34)) -> Manager & Sales & Marketing | U34: =IF(V34="","",INDEX('Backing 4'!Z:Z,MATCH(V34,'Backing 4'!Y:Y,0))) -> #N/A | V34: =IF(O34="","",IF(D34="1 - Executive","",D34)) -> Manager | W34: 1 | X34: =IF(E34="Y","",IF(Y34="Y",INDEX('Backing 2'!B:B,MATCH(D34,'Backing 2'!C:C,0)),D34)) -> #N/A | Y34: Y | Z34: 1 | AA34: 30 to 39 | AB34: 33 | AC34: Germany | AD34: Europe | AE34: Europe | AF34: 41730 | AG34: 6 | AH34: =RAND() -> 0.8178633
A35: 34 | B35: Female | C35: 5 | D35: Senior Officer | E35: N | F35: 1 | G35: Yes | H35: Yes | I35: 0.5 | J35: No | K35: Y | L35: Internal Services | M35: 0 | N35: 4 | O35: Manager | P35: Internal Services | Q35: Full Time | R35: Full Time | S35: =IF(T35="","",INDEX('Backing 4'!U:U,MATCH(T35,'Backing 4'!T:T,0))) -> #N/A | T35: =IF(O35="","",IF(D35="1 - Executive","",D35&" & "&P35)) -> Senior Officer & Internal Services | U35: =IF(V35="","",INDEX('Backing 4'!Z:Z,MATCH(V35,'Backing 4'!Y:Y,0))) -> #N/A | V35: =IF(O35="","",IF(D35="1 - Executive","",D35)) -> Senior Officer | W35: 5 | X35: =IF(E35="Y","",IF(Y35="Y",INDEX('Backing 2'!B:B,MATCH(D35,'Backing 2'!C:C,0)),D35)) -> Senior Officer | Y35: N | Z35: 2 | AA35: 30 to 39 | AB35: 37 | AC35: Switzerland | AD35: Switzerland | AE35: Switzerland | AF35: 41730 | AG35: 6 | AH35: =RAND() -> 0.39186237
A36: 35 | B36: Male | C36: 5 | D36: Senior Officer | E36: N | F36: 3 | G36: No | H36: Yes | I36: 0.5 | J36: No | K36: Y | L36: Internal Services | M36: 0 | N36: 5 | O36: Senior Officer | P36: Internal Services | Q36: Full Time | R36: Full Time | S36: =IF(T36="","",INDEX('Backing 4'!U:U,MATCH(T36,'Backing 4'!T:T,0))) -> #N/A | T36: =IF(O36="","",IF(D36="1 - Executive","",D36&" & "&P36)) -> Senior Officer & Internal Services | U36: =IF(V36="","",INDEX('Backing 4'!Z:Z,MATCH(V36,'Backing 4'!Y:Y,0))) -> #N/A | V36: =IF(O36="","",IF(D36="1 - Executive","",D36)) -> Senior Officer | W36: 3 | X36: =IF(E36="Y","",IF(Y36="Y",INDEX('Backing 2'!B:B,MATCH(D36,'Backing 2'!C:C,0)),D36)) -> Senior Officer | Y36: N | Z36: 0 | AA36: 20 to 29 | AB36: 27 | AC36: Switzerland | AD36: Switzerland | AE36: Switzerland | AF36: 42826 | AG36: 3 | AH36: =RAND() -> 0.63646305
... A45: 44 | B45: Female | C45: 6 | D45: Junior Officer | E45: N | F45: 2 | G45: No | H45: Yes | I45: 0.5 | J45: No | K45: Y | L45: Sales & Marketing | M45: 0 | N45: 6 | O45: Junior Officer | P45: Sales & Marketing | Q45: Full Time | R45: Full Time | S45: =IF(T45="","",INDEX('Backing 4'!U:U,MATCH(T45,'Backing 4'!T:T,0))) -> #N/A | T45: =IF(O45="","",IF(D45="1 - Executive","",D45&" & "&P45)) -> Junior Officer & Sales & Marketing | U45: =IF(V45="","",INDEX('Backing 4'!Z:Z,MATCH(V45,'Backing 4'!Y:Y,0))) -> #N/A | V45: =IF(O45="","",IF(D45="1 - Executive","",D45)) -> Junior Officer | W45: 2 | X45: =IF(E45="Y","",IF(Y45="Y",INDEX('Backing 2'!B:B,MATCH(D45,'Backing 2'!C:C,0)),D45)) -> Junior Officer | Y45: N | Z45: 2 | AA45: 20 to 29 | AB45: 23 | AC45: Italy | AD45: Europe | AE45: Europe | AF45: 43191 | AG45: 2 | AH45: =RAND() -> 0.29495879
A46: 45 | B46: Male | C46: 2 | D46: Director | E46: N | F46: 2 | G46: No | H46: No | I46: 0.5 | J46: Yes | K46: Y | L46: Internal Services | M46: FY20 | N46: 0 | O46: NOT AVAILABLE | P46: Internal Services | Q46: Full Time | R46: Full Time | S46: =IF(T46="","",INDEX('Backing 4'!U:U,MATCH(T46,'Backing 4'!T:T,0))) -> #N/A | T46: =IF(O46="","",IF(D46="1 - Executive","",D46&" & "&P46)) -> Director & Internal Services | U46: =IF(V46="","",INDEX('Backing 4'!Z:Z,MATCH(V46,'Backing 4'!Y:Y,0))) -> #N/A | V46: =IF(O46="","",IF(D46="1 - Executive","",D46)) -> Director | W46: 3 | X46: =IF(E46="Y","",IF(Y46="Y",INDEX('Backing 2'!B:B,MATCH(D46,'Backing 2'!C:C,0)),D46)) -> Director | Y46: N | Z46: 3 | AA46: 50 to 59 | AB46: 54 | AC46: Switzerland | AD46: Switzerland | AE46: Switzerland | AF46: 40634 | AG46: 9 | AH46: =RAND() -> 0.73520817
A47: 46 | B47: Male | C47: 6 | D47: Junior Officer | E47: N | F47: 2 | G47: No | H47: Yes | I47: 0.5 | J47: No | K47: Y | L47: Internal Services | M47: 0 | N47: 6 | O47: Junior Officer | P47: Internal Services | Q47: Full Time | R47: Full Time | S47: =IF(T47="","",INDEX('Backing 4'!U:U,MATCH(T47,'Backing 4'!T:T,0))) -> #N/A | T47: =IF(O47="","",IF(D47="1 - Executive","",D47&" & "&P47)) -> Junior Officer & Internal Services | U47: =IF(V47="","",INDEX('Backing 4'!Z:Z,MATCH(V47,'Backing 4'!Y:Y,0))) -> #N/A | V47: =IF(O47="","",IF(D47="1 - Executive","",D47)) -> Junior Officer | W47: 3 | X47: =IF(E47="Y","",IF(Y47="Y",INDEX('Backing 2'!B:B,MATCH(D47,'Backing 2'!C:C,0)),D47)) -> Junior Officer | Y47: N | Z47: 3 | AA47: 20 to 29 | AB47: 26 | AC47: France | AD47: Europe | AE47: Europe | AF47: 42826 | AG47: 3 | AH47: =RAND() -> 0.3768689
A48: 47 | B48: Female | C48: 4 | D48: Manager | E48: N | F48: 2 | G48: No | H48: Yes | I48: 0.5 | J48: No | K48: Y | L48: HR | M48: 0 | N48: 4 | O48: Manager | P48: HR | Q48: Full Time | R48: Full Time | S48: =IF(T48="","",INDEX('Backing 4'!U:U,MATCH(T48,'Backing 4'!T:T,0))) -> #N/A | T48: =IF(O48="","",IF(D48="1 - Executive","",D48&" & "&P48)) -> Manager & HR | U48: =IF(V48="","",INDEX('Backing 4'!Z:Z,MATCH(V48,'Backing 4'!Y:Y,0))) -> #N/A | V48: =IF(O48="","",IF(D48="1 - Executive","",D48)) -> Manager | W48: 2 | X48: =IF(E48="Y","",IF(Y48="Y",INDEX('Backing 2'!B:B,MATCH(D48,'Backing 2'!C:C,0)),D48)) -> Manager | Y48: N | Z48: 3 | AA48: 30 to 39 | AB48: 36 | AC48: Austria | AD48: Europe | AE48: Europe | AF48: 42461 | AG48: 4 | AH48: =RAND() -> 0.038337846
...

Sheet Sheet1

Sheet Backing 1
A1: RAND | B1: Employee ID | C1: GENDER | D1: GRADE | E1: Position | F1: FUNCTION | G1: OC_RATE | H1: PERFORM | I1: Y_GRADE | J1: AGE | K1: Y_SERVIC | L1: Nationality | M1: Rank 2
A2: =RAND() -> 0.61797765 | B2: 1 | C2: Male | D2: 1 | E2: Junior Officer | F2: Operations | G2: 1 | H2: 2 | I2: 1 | J2: 48 | K2: 6 | L2: Spain | M2: 74
A3: =RAND() -> 0.56541998 | B3: 2 | C3: Female | D3: 3 | E3: Manager | F3: Sales & Marketing | G3: 1 | H3: 2 | I3: 3 | J3: 29 | K3: 1 | L3: Germany | M3: 320
A4: =RAND() -> 0.44003835 | B4: 3 | C4: Male | D4: 5 | E4: Director | F4: Strategy | G4: 1 | H4: 3 | I4: 1 | J4: 31 | K4: 5 | L4: Switzerland | M4: 66
A5: =RAND() -> 0.43699271 | B5: 4 | C5: Male | D5: 3 | E5: Manager | F5: HR | G5: 1 | H5: 3 | I5: 1 | J5: 27 | K5: 1 | L5: Germany | M5: 153
A6: =RAND() -> 0.93100647 | B6: 5 | C6: Female | D6: 1 | E6: Junior Officer | F6: Sales & Marketing | G6: 1 | H6: 3 | I6: 4 | J6: 36 | K6: 1 | L6: Switzerland | M6: 460
A7: =RAND() -> 0.60237099 | B7: 6 | C7: Male | D7: 3 | E7: Manager | F7: Internal Services | G7: 1 | H7: 2 | I7: 3 | J7: 49 | K7: 0 | L7: Switzerland | M7: 339
A8: =RAND() -> 0.44386798 | B8: 7 | C8: Male | D8: 4 | E8: Senior Manager | F8: Operations | G8: 1 | H8: 2 | I8: 3 | J8: 47 | K8: 0 | L8: Italy | M8: 335
A9: =RAND() -> 0.73601847 | B9: 8 | C9: Female | D9: 2 | E9: Senior Officer | F9: HR | G9: 1 | H9: 2 | I9: 2 | J9: 44 | K9: 7 | L9: Switzerland | M9: 197
A10: =RAND() -> 0.21415199 | B10: 9 | C10: Male | D10: 1 | E10: Junior Officer | F10: Sales & Marketing | G10: 1 | H10: 2 | I10: 3 | J10: 43 | K10: 4 | L10: United States | M10: 356
A11: =RAND() -> 0.59458344 | B11: 10 | C11: Male | D11: 1 | E11: Junior Officer | F11: Internal Services | G11: 1 | H11: 2 | I11: 1 | J11: 58 | K11: 3 | L11: Switzerland | M11: 100
A12: =RAND() -> 0.30467492 | B12: 11 | C12: Male | D12: 3 | E12: Manager | F12: Operations | G12: 1 | H12: 2 | I12: 5 | J12: 49 | K12: 9 | L12: Switzerland | M12: 463
A13: =RAND() -> 0.37000014 | B13: 12 | C13: Male | D13: 2 | E13: Senior Officer | F13: Strategy | G13: 1 | H13: 2 | I13: 3 | J13: 43 | K13: 7 | L13: France | M13: 341
... A501: =RAND() -> 0.51562298 | B501: 500 | C501: Male | D501: 4 | E501: Senior Manager | F501: Operations | G501: 1 | H501: 2 | I501: 3 | J501: 43 | K501: 9 | L501: Switzerland | M501: 354

Sheet Backing 2
B2: 3 - Senior Manager | C2: 2 - Director
B3: 5 - Senior Officer | C3: 4 - Manager
B4: 6 - Junior Officer | C4: 5 - Senior Officer
B5: 4 - Manager | C5: 3 - Senior Manager
B6: 2 - Director | C6: 1 - Executive

Sheet Backing 3
E2: =SUM(E3:E23) -> 500
C3: 1 | D3: United States | E3: 6
C4: 2 | D4: Belgium | E4: 1
C5: 3 | D5: United Kingdom | E5: 8
C6: 4 | D6: Canada | E6: 1
C7: 5 | D7: China | E7: 1
C8: 6 | D8: Austria | E8: 5
C9: 7 | D9: Denmark | E9: 1
C10: 8 | D10: Netherlands | E10: 4
C11: 9 | D11: France | E11: 92
C12: 10 | D12: Germany | E12: 65
C13: 11 | D13: Greece | E13: 1
C14: 12 | D14: Russia | E14: 2
... C23: 21 | D23: Switzerland | E23: 268

Sheet Backing 4
E1: 1 | F1: 2 | G1: 3 | H1: 4 | I1: 5 | J1: 6
E2: =SUM(E4:E9) -> 191 | F2: =SUM(F4:F9) -> 103 | G2: =SUM(G4:G9) -> 87 | H2: =SUM(H4:H9) -> 62 | I2: =SUM(I4:I9) -> 38 | J2: =SUM(J4:J9) -> 19 | Q2: Total | R2: F | S2: M
E3: 191 | F3: 103 | G3: 87 | H3: 62 | I3: 38 | J3: 19 | Q3: =COUNTIF('Pharma Group AG'!$T:$T,T3) -> 0 | T3: 2 - Director & Finance | U3: Inconclusive | Y3: 2 - Director | Z3: Even
C4: Finance | E4: 4 | F4: 4 | G4: 4 | H4: 3 | I4: 2 | J4: 1 | Q4: =COUNTIF('Pharma Group AG'!$T:$T,T4) -> 0 | T4: 2 - Director & HR | U4: Inconclusive | Y4: 3 - Senior Manager | Z4: Uneven - Men benefit
C5: HR | E5: 4 | F5: 3 | G5: 4 | H5: 3 | I5: 2 | J5: 1 | Q5: =COUNTIF('Pharma Group AG'!$T:$T,T5) -> 0 | T5: 2 - Director & Internal Services | U5: Inconclusive | Y5: 4 - Manager | Z5: Even
C6: Internal Services | E6: 25 | F6: 12 | G6: 14 | H6: 10 | I6: 10 | J6: 2 | Q6: =COUNTIF('Pharma Group AG'!$T:$T,T6) -> 0 | T6: 2 - Director & Operations | U6: Even | Y6: 5 - Senior Officer | Z6: Even
C7: Operations | E7: 98 | F7: 38 | G7: 35 | H7: 24 | I7: 11 | J7: 1 | Q7: =COUNTIF('Pharma Group AG'!$T:$T,T7) -> 0 | T7: 2 - Director & Sales & Marketing | U7: Inconclusive | Y7: 6 - Junior Officer | Z7: Even
C8: Sales & Marketing | E8: 58 | F8: 44 | G8: 28 | H8: 20 | I8: 10 | J8: 1 | Q8: =COUNTIF('Pharma Group AG'!$T:$T,T8) -> 0 | T8: 2 - Director & Strategy | U8: Inconclusive
C9: Strategy | E9: 2 | F9: 2 | G9: 2 | H9: 2 | I9: 3 | J9: 13 | Q9: =COUNTIF('Pharma Group AG'!$T:$T,T9) -> 0 | T9: 3 - Senior Manager & Finance | U9: Inconclusive
Q10: =COUNTIF('Pharma Group AG'!$T:$T,T10) -> 0 | T10: 3 - Senior Manager & HR | U10: Inconclusive
Q11: =COUNTIF('Pharma Group AG'!$T:$T,T11) -> 0 | T11: 3 - Senior Manager & Internal Services | U11: Uneven - Men benefit
Q12: =COUNTIF('Pharma Group AG'!$T:$T,T12) -> 0 | T12: 3 - Senior Manager & Operations | U12: Even
Q13: =COUNTIF('Pharma Group AG'!$T:$T,T13) -> 0 | T13: 3 - Senior Manager & Sales & Marketing | U13: Uneven - Men benefit
Q14: =COUNTIF('Pharma Group AG'!$T:$T,T14) -> 0 | T14: 3 - Senior Manager & Strategy | U14: Inconclusive
J15: 1 | K15: 2 | M15: 1 | N15: 0 | Q15: =COUNTIF('Pharma Group AG'!$T:$T,T15) -> 0 | T15: 4 - Manager & Finance | U15: Inconclusive
J16: 2 | K16: 3 | M16: 2 | N16: 0 | Q16: =COUNTIF('Pharma Group AG'!$T:$T,T16) -> 0 | T16: 4 - Manager & HR | U16: Inconclusive
J17: 3 | K17: 2 | M17: 3 | N17: 0 | Q17: =COUNTIF('Pharma Group AG'!$T:$T,T17) -> 0 | T17: 4 - Manager & Internal Services | U17: Even
J18: 4 | K18: 2 | M18: 4 | N18: 0 | Q18: =COUNTIF('Pharma Group AG'!$T:$T,T18) -> 0 | T18: 4 - Manager & Operations | U18: Even
J19: 5 | K19: 3 | M19: 5 | N19: 0 | Q19: =COUNTIF('Pharma Group AG'!$T:$T,T19) -> 0 | T19: 4 - Manager & Sales & Marketing | U19: Uneven - Men benefit
J20: 6 | K20: 2 | M20: 6 | N20: 0 | Q20: =COUNTIF('Pharma Group AG'!$T:$T,T20) -> 0 | T20: 4 - Manager & Strategy | U20: Inconclusive
J21: 7 | K21: 2 | M21: 7 | N21: 0 | Q21: =COUNTIF('Pharma Group AG'!$T:$T,T21) -> 0 | T21: 5 - Senior Officer & Finance | U21: Inconclusive
J22: 8 | K22: 2 | M22: 8 | N22: 0 | Q22: =COUNTIF('Pharma Group AG'!$T:$T,T22) -> 0 | T22: 5 - Senior Officer & HR | U22: Inconclusive
J23: 9 | K23: 2 | M23: 9 | N23: 0 | Q23: =COUNTIF('Pharma Group AG'!$T:$T,T23) -> 0 | T23: 5 - Senior Officer & Internal Services | U23: Even
J24: 10 | K24: 2 | M24: 10 | N24: 0 | Q24: =COUNTIF('Pharma Group AG'!$T:$T,T24) -> 0 | T24: 5 - Senior Officer & Operations | U24: Even
J25: 11 | K25: 2 | M25: 11 | N25: 0 | Q25: =COUNTIF('Pharma Group AG'!$T:$T,T25) -> 0 | T25: 5 - Senior Officer & Sales & Marketing | U25: Even
J26: 12 | K26: 2 | M26: 12 | N26: 0 | Q26: =COUNTIF('Pharma Group AG'!$T:$T,T26) -> 0 | T26: 5 - Senior Officer & Strategy | U26: Inconclusive
... J32: 18 | K32: 0 | M32: 18 | N32: 0 | Q32: =COUNTIF('Pharma Group AG'!$T:$T,T32) -> 0 | T32: 6 - Junior Officer & Strategy | U32: Inconclusive
J33: 19 | K33: 0 | M33: 19 | N33: 0
J34: 20 | K34: 1 | M34: 20 | N34: 0
J35: 21 | K35: 2 | M35: 21 | N35: 0
J36: 22 | K36: 3 | M36: 22 | N36: 0
J37: 23 | K37: 2 | M37: 23 | N37: 0
J38: 24 | K38: 2 | M38: 24 | N38: 0
J39: 25 | K39: 2 | M39: 25 | N39: 0
J40: 26 | K40: 2 | M40: 26 | N40: 0
J41: 27 | K41: 2 | M41: 27 | N41: 0
J42: 28 | K42: 3 | M42: 28 | N42: 0
J43: 29 | K43: 2 | M43: 29 | N43: 0
J44: 30 | K44: 2 | M44: 30 | N44: 0
... J514: 500 | K514: 3 | M514: 500 | N514: 9

Sheet Sheet2
